<mujoco model="spot">
  <compiler angle="radian" meshdir="../../../../../mujoco_menagerie/boston_dynamics_spot/assets" autolimits="true"/>

  <option iterations="1" ls_iterations="5" timestep="0.004">
    <flag eulerdamp="disable"/>
  </option>

  <asset>
    <material name="BlackAbs" rgba="0.1 0.1 0.1 1"/>
    <material name="wrap" rgba="0.878431 0.666666 0.227450 1"/>

    <mesh file="body_0.obj"/>
    <mesh file="body_1.obj"/>
    <mesh file="front_left_hip.obj"/>
    <mesh file="front_left_upper_leg_0.obj"/>
    <mesh file="front_left_upper_leg_1.obj"/>
    <mesh file="front_left_lower_leg.obj"/>
    <mesh file="front_right_hip.obj"/>
    <mesh file="front_right_upper_leg_0.obj"/>
    <mesh file="front_right_upper_leg_1.obj"/>
    <mesh file="front_right_lower_leg.obj"/>
    <mesh file="rear_left_hip.obj"/>
    <mesh file="rear_left_upper_leg_0.obj"/>
    <mesh file="rear_left_upper_leg_1.obj"/>
    <mesh file="rear_left_lower_leg.obj"/>
    <mesh file="rear_right_hip.obj"/>
    <mesh file="rear_right_upper_leg_0.obj"/>
    <mesh file="rear_right_upper_leg_1.obj"/>
    <mesh file="rear_right_lower_leg.obj"/>
  </asset>

  <default>
    <default class="spot">
      <geom condim="1" friction="0.6"/>
      <joint actuatorfrcrange="-1000 1000" damping="20" armature="0.1" frictionloss="0.2"/>
      <position kp="400" inheritrange="1"/>
      <default class="visual">
        <geom group="2" type="mesh" contype="0" conaffinity="0"/>
      </default>
      <default class="collision">
        <geom group="3" type="capsule" contype="0" conaffinity="1"/>
        <default class="foot">
          <geom type="sphere" size="0.036" pos="0 0 -0.3365" solimp="0.9 .95 0.023" friction="1.0" condim="3"/>
          <site size="0.036" group="5" pos="0 0 -0.3365"/>
        </default>
      </default>
    </default>
  </default>

  <worldbody>
    <light name="spotlight" mode="targetbodycom" target="body" pos="3 0 4"/>
    <body name="body" childclass="spot" pos="0 0 .75">
      <camera name="track" pos="0.846 -1.3 0.316" xyaxes="0.866 0.500 0.000 -0.171 0.296 0.940" mode="trackcom"/>
      <camera name="top" pos="-1 0 1" xyaxes="0 -1 0 0.7 0 0.7" mode="trackcom"/>
      <camera name="side" pos="0 -1.2 .3" xyaxes="1 0 0 0 1 2" mode="trackcom"/>
      <camera name="back" pos="-1.2 0 .3" xyaxes="0 -1 0 1 0 2" mode="trackcom"/>
      <freejoint name="freejoint"/>
      <inertial pos="0.0063944 -9.81216e-05 0.000911379" mass="32.86" diaginertia="0.13144 0.13144 0.13144"/>
      <geom mesh="body_0" material="BlackAbs" class="visual"/>
      <geom mesh="body_1" material="wrap" class="visual"/>
      <geom class="collision" quat="1 0 1 0" pos="0 -0.02 0" size="0.08 0.425" type="cylinder"/>
      <geom class="collision" quat="1 0 1 0" pos="0 +0.02 0" size="0.08 0.425" type="cylinder"/>
      <site name="imu"/>
      <body name="fl_hip" pos="0.29785 0.055 0">
        <inertial pos="-0.00537435 0.0128418 9.87523e-05" quat="1 1 -1 1" mass="1.68"
          diaginertia="0.00226544 0.00211474 0.00181296"/>
        <joint name="fl_hx" axis="1 0 0" range="-0.785398 0.785398"/>
        <geom material="BlackAbs" mesh="front_left_hip" class="visual"/>
        <body name="fl_uleg" pos="0 0.1108 0">
          <inertial pos="0.00514237 -0.00243237 -0.121009" mass="2.34" diaginertia="0.0275596 0.0273549 0.00284815"/>
          <joint name="fl_hy" axis="0 1 0" range="-0.898845 2.29511"/>
          <geom mesh="front_left_upper_leg_0" material="wrap" class="visual"/>
          <geom mesh="front_left_upper_leg_1" material="BlackAbs" class="visual"/>
          <geom size="0.035" fromto="0 .01 0.03 0 .01 -0.3" class="collision"/>
          <body name="fl_lleg" pos="0.025 0 -0.32">
            <inertial pos="0.00225794 4.6076e-05 -0.180082" quat="1 0 0 1" mass="0.35"
              diaginertia="0.00405032 0.00399902 0.00014934"/>
            <joint name="fl_kn" axis="0 1 0" range="-2.7929 -0.254402"/>
            <geom material="BlackAbs" mesh="front_left_lower_leg" class="visual"/>
            <geom size="0.02" fromto="0 0 0.03 0.025 0 -0.13" class="collision"/>
            <geom size="0.015" fromto="0.03 0 -0.15 0.02 0 -0.33" class="collision"/>
            <geom name="FL" class="foot"/>
            <site name="FL" class="foot"/>
          </body>
        </body>
      </body>
      <body name="fr_hip" pos="0.29785 -0.055 0">
        <inertial pos="-0.00537435 -0.0128418 -9.87523e-05" quat="1 1 -1 1" mass="1.68"
          diaginertia="0.00226544 0.00211474 0.00181296"/>
        <joint name="fr_hx" axis="1 0 0" range="-0.785398 0.785398"/>
        <geom material="BlackAbs" mesh="front_right_hip" class="visual"/>
        <body name="fr_uleg" pos="0 -0.1108 0">
          <inertial pos="0.00514237 0.00243237 -0.121009" mass="2.34" diaginertia="0.0275596 0.0273549 0.00284815"/>
          <joint name="fr_hy" axis="0 1 0" range="-0.898845 2.24363"/>
          <geom mesh="front_right_upper_leg_0" material="wrap" class="visual"/>
          <geom mesh="front_right_upper_leg_1" material="BlackAbs" class="visual"/>
          <geom size="0.035" fromto="0 .01 0.03 0 .01 -0.3" class="collision"/>
          <body name="fr_lleg" pos="0.025 0 -0.32">
            <inertial pos="0.00225794 4.6076e-05 -0.180082" quat="1 0 0 1" mass="0.35"
              diaginertia="0.00405032 0.00399902 0.00014934"/>
            <joint name="fr_kn" axis="0 1 0" range="-2.7929 -0.255648"/>
            <geom material="BlackAbs" mesh="front_right_lower_leg" class="visual"/>
            <geom size="0.02" fromto="0 0 0.03 0.025 0 -0.13" class="collision"/>
            <geom size="0.015" fromto="0.03 0 -0.15 0.02 0 -0.33" class="collision"/>
            <geom name="FR" class="foot"/>
            <site name="FR" class="foot"/>
          </body>
        </body>
      </body>
      <body name="hl_hip" pos="-0.29785 0.055 0">
        <inertial pos="0.00537435 0.0128418 -9.87523e-05" quat="1 1 -1 1" mass="1.68"
          diaginertia="0.00226544 0.00211474 0.00181296"/>
        <joint name="hl_hx" axis="1 0 0" range="-0.785398 0.785398"/>
        <geom material="BlackAbs" mesh="rear_left_hip" class="visual"/>
        <body name="hl_uleg" pos="0 0.1108 0">
          <inertial pos="0.00514237 -0.00243237 -0.121009" mass="2.34" diaginertia="0.0275596 0.0273549 0.00284815"/>
          <joint name="hl_hy" axis="0 1 0" range="-0.898845 2.29511"/>
          <geom mesh="rear_left_upper_leg_0" material="wrap" class="visual"/>
          <geom mesh="rear_left_upper_leg_1" material="BlackAbs" class="visual"/>
          <geom size="0.035" fromto="0 .01 0.03 0 .01 -0.3" class="collision"/>
          <body name="hl_lleg" pos="0.025 0 -0.32">
            <inertial pos="0.00225794 4.6076e-05 -0.180082" quat="1 0 0 1" mass="0.35"
              diaginertia="0.00405032 0.00399902 0.00014934"/>
            <joint name="hl_kn" axis="0 1 0" range="-2.7929 -0.247067"/>
            <geom material="BlackAbs" mesh="rear_left_lower_leg" class="visual"/>
            <geom size="0.02" fromto="0 0 0.03 0.025 0 -0.13" class="collision"/>
            <geom size="0.015" fromto="0.03 0 -0.15 0.02 0 -0.33" class="collision"/>
            <geom name="HL" class="foot"/>
            <site name="HL" class="foot"/>
          </body>
        </body>
      </body>
      <body name="hr_hip" pos="-0.29785 -0.055 0">
        <inertial pos="0.00537435 -0.0128418 9.87523e-05" quat="1 1 -1 1" mass="1.68"
          diaginertia="0.00226544 0.00211474 0.00181296"/>
        <joint name="hr_hx" axis="1 0 0" range="-0.785398 0.785398"/>
        <geom material="BlackAbs" mesh="rear_right_hip" class="visual"/>
        <body name="hr_uleg" pos="0 -0.1108 0">
          <inertial pos="0.00514237 0.00243237 -0.121009" mass="2.34" diaginertia="0.0275596 0.0273549 0.00284815"/>
          <joint name="hr_hy" axis="0 1 0" range="-0.898845 2.29511"/>
          <geom mesh="rear_right_upper_leg_0" material="wrap" class="visual"/>
          <geom mesh="rear_right_upper_leg_1" material="BlackAbs" class="visual"/>
          <geom size="0.035" fromto="0 .01 0.03 0 .01 -0.3" class="collision"/>
          <body name="hr_lleg" pos="0.025 0 -0.32">
            <inertial pos="0.00225794 4.6076e-05 -0.180082" quat="1 0 0 1" mass="0.35"
              diaginertia="0.00405032 0.00399902 0.00014934"/>
            <joint name="hr_kn" axis="0 1 0" range="-2.7929 -0.248282"/>
            <geom material="BlackAbs" mesh="rear_left_lower_leg" class="visual"/>
            <geom size="0.02" fromto="0 0 0.03 0.025 0 -0.13" class="collision"/>
            <geom size="0.015" fromto="0.03 0 -0.15 0.02 0 -0.33" class="collision"/>
            <geom name="HR" class="foot"/>
            <site name="HR" class="foot"/>
          </body>
        </body>
      </body>
    </body>
  </worldbody>

  <contact>
    <exclude body1="body" body2="fl_uleg"/>
    <exclude body1="body" body2="fr_uleg"/>
    <exclude body1="body" body2="hl_uleg"/>
    <exclude body1="body" body2="hr_uleg"/>
  </contact>

  <actuator>
    <position class="spot" name="fl_hx" joint="fl_hx"/>
    <position class="spot" name="fl_hy" joint="fl_hy"/>
    <position class="spot" name="fl_kn" joint="fl_kn"/>
    <position class="spot" name="fr_hx" joint="fr_hx"/>
    <position class="spot" name="fr_hy" joint="fr_hy"/>
    <position class="spot" name="fr_kn" joint="fr_kn"/>
    <position class="spot" name="hl_hx" joint="hl_hx"/>
    <position class="spot" name="hl_hy" joint="hl_hy"/>
    <position class="spot" name="hl_kn" joint="hl_kn"/>
    <position class="spot" name="hr_hx" joint="hr_hx"/>
    <position class="spot" name="hr_hy" joint="hr_hy"/>
    <position class="spot" name="hr_kn" joint="hr_kn"/>
  </actuator>

  <sensor>
    <framepos objtype="site" objname="imu" name="position"/>
    <gyro site="imu" name="gyro"/>
    <velocimeter site="imu" name="local_linvel"/>
    <accelerometer site="imu" name="accelerometer"/>
    <framezaxis objtype="site" objname="imu" name="upvector"/>
    <framexaxis objtype="site" objname="imu" name="forwardvector"/>
    <framelinvel objtype="site" objname="imu" name="global_linvel"/>
    <frameangvel objtype="site" objname="imu" name="global_angvel"/>
    <framequat objtype="site" objname="imu" name="orientation"/>
    <framelinvel objtype="site" objname="FR" name="FR_global_linvel"/>
    <framelinvel objtype="site" objname="FL" name="FL_global_linvel"/>
    <framelinvel objtype="site" objname="HR" name="HR_global_linvel"/>
    <framelinvel objtype="site" objname="HL" name="HL_global_linvel"/>
  </sensor>
</mujoco>
