<?xml version='1.0' encoding='UTF-8'?>
<mujoco model="kawaru">
  <compiler angle="degree" coordinate="local" inertiafromgeom="true"/>
  <option integrator="RK4" timestep="0.01"/>
  <default>
    <default class="kawaru">
      <!-- This globaly disables all collisions. -->
      <geom condim="1" contype="0" conaffinity="0" density="5.0" friction="1 0.5 0.5" margin="0.01" rgba="0.8 0.6 0.4 1"/>
    </default>
    <joint armature="1" damping="1" limited="true"/>
    <site type="sphere" size="0.02" rgba="0.5 0.5 0.5 1"/>
  </default>
  <asset>
    <texture name="skybox" type="skybox" builtin="gradient" rgb1=".4 .6 .8" rgb2="0 0 0" width="800" height="800" mark="random" markrgb="1 1 1"/>
    <texture builtin="gradient" height="80" rgb1="1 1 1" rgb2="0 0 0" type="skybox" width="80"/>
    <texture builtin="flat" height="1278" mark="cross" markrgb="1 1 1" name="texgeom" random="0.01" rgb1="0.8 0.6 0.4" rgb2="0.8 0.6 0.4" type="cube" width="127"/>
    <texture builtin="checker" height="80" name="texplane" rgb1="0 0 0" rgb2="0.8 0.8 0.8" type="2d" width="80"/>
    <material name="MatPlane" reflectance="0.5" shininess="1" specular="1" texrepeat="60 60" texture="texplane"/>
    <material name="geom" texture="texgeom" texuniform="true"/>
  </asset>
  <worldbody>
    <!-- <light name="worldbody_light_1" mode="targetbodycom" target="base" pos="0 -1 2" cutoff="30"/> -->
    <body name="base" pos="0 0 0.75" childclass="kawaru">
      <camera name="base_camera_1" mode="trackcom" pos="0 -1 0.3" xyaxes="1 0 0 0 0 1"/>
      <geom name="base_geom_1" pos="0 0 0" size="0.3 0.2 0.05" type="box"/>
      <freejoint/>
      <site name="base_site_1" pos="-0.24 0.2 0.0"/>
      <site name="base_site_2" pos="-0.12 0.2 0.0"/>
      <site name="base_site_3" pos="0.0 0.2 0.0"/>
      <site name="base_site_4" pos="0.12 0.2 0.0"/>
      <site name="base_site_5" pos="0.24 0.2 0.0"/>
      <site name="base_site_6" pos="-0.24 -0.2 0.0"/>
      <site name="base_site_7" pos="-0.12 -0.2 0.0"/>
      <site name="base_site_8" pos="0.0 -0.2 0.0"/>
      <site name="base_site_9" pos="0.12 -0.2 0.0"/>
      <site name="base_site_10" pos="0.24 -0.2 0.0"/>
      <site name="imu" pos="0. 0. 0."/>
      <body name="L1_D1" pos="0.24 0.2 0">
        <joint axis="1 0 0" name="L1_D1_joint_1" pos="0.0 0.0 0.0" range="-180 180" type="hinge"/>
        <geom fromto="0.0 0.0 0.0 0. 0.2 0.0" name="L1_D1_geom_1" size="0.04" type="capsule"/>
        <body pos="0.0 0.2 0.0" name="L1_D2">
          <joint axis="0 0 1" name="L1_D2_joint_1" pos="0.0 0.0 0.0" range="-180 180" type="hinge"/>
          <geom fromto="0.0 0.0 0.0 0. 0.2 0.0" name="L1_D2_geom_1" size="0.04" type="capsule"/>
          <body pos="0.0 0.2 0.0" name="L1_D3">
            <joint axis="0 0 1" name="L1_D3_joint_1" pos="0.0 0.0 0.0" range="-180 180" type="hinge"/>
            <geom fromto="0.0 0.0 0.0 0. 0.2 0.0" name="L1_D3_geom_1" size="0.04" type="capsule" contype="0" conaffinity="1"/>
          </body>
        </body>
      </body>
      <body name="L2_D1" pos="-0.24 0.2 0">
        <joint axis="1 0 0" name="L2_D1_joint_1" pos="0.0 0.0 0.0" range="-180 180" type="hinge"/>
        <geom fromto="0.0 0.0 0.0 0. 0.2 0.0" name="L2_D1_geom_1" size="0.04" type="capsule"/>
        <body pos="0.0 0.2 0.0" name="L2_D2">
          <joint axis="0 0 1" name="L2_D2_joint_1" pos="0.0 0.0 0.0" range="-180 180" type="hinge"/>
          <geom fromto="0.0 0.0 0.0 0. 0.2 0.0" name="L2_D2_geom_1" size="0.04" type="capsule"/>
          <body pos="0.0 0.2 0.0" name="L2_D3">
            <joint axis="0 0 1" name="L2_D3_joint_1" pos="0.0 0.0 0.0" range="-180 180" type="hinge"/>
            <geom fromto="0.0 0.0 0.0 0. 0.2 0.0" name="L2_D3_geom_1" size="0.04" type="capsule" contype="0" conaffinity="1"/>
          </body>
        </body>
      </body>
      <body name="L3_D1" pos="-0.24 -0.2 0">
        <joint axis="-1 0 0" name="L3_D1_joint_1" pos="0.0 0.0 0.0" range="-180 180" type="hinge"/>
        <geom fromto="0.0 0.0 0.0 0. -0.2 0.0" name="L3_D1_geom_1" size="0.04" type="capsule"/>
        <body pos="0.0 -0.2 0.0" name="L3_D2">
          <joint axis="0 0 -1" name="L3_D2_joint_1" pos="0.0 0.0 0.0" range="-180 180" type="hinge"/>
          <geom fromto="0.0 0.0 0.0 0. -0.2 0.0" name="L3_D2_geom_1" size="0.04" type="capsule"/>
          <body pos="0.0 -0.2 0.0" name="L3_D3">
            <joint axis="0 0 -1" name="L3_D3_joint_1" pos="0.0 0.0 0.0" range="-180 180" type="hinge"/>
            <geom fromto="0.0 0.0 0.0 0. -0.2 0.0" name="L3_D3_geom_1" size="0.04" type="capsule" contype="0" conaffinity="1"/>
          </body>
        </body>
      </body>
      <body name="L4_D1" pos="0.24 -0.2 0">
        <joint axis="-1 0 0" name="L4_D1_joint_1" pos="0.0 0.0 0.0" range="-180 180" type="hinge"/>
        <geom fromto="0.0 0.0 0.0 0. -0.2 0.0" name="L4_D1_geom_1" size="0.04" type="capsule"/>
        <body pos="0.0 -0.2 0.0" name="L4_D2">
          <joint axis="0 0 -1" name="L4_D2_joint_1" pos="0.0 0.0 0.0" range="-180 180" type="hinge"/>
          <geom fromto="0.0 0.0 0.0 0. -0.2 0.0" name="L4_D2_geom_1" size="0.04" type="capsule"/>
          <body pos="0.0 -0.2 0.0" name="L4_D3">
            <joint axis="0 0 -1" name="L4_D3_joint_1" pos="0.0 0.0 0.0" range="-180 180" type="hinge"/>
            <geom fromto="0.0 0.0 0.0 0. -0.2 0.0" name="L4_D3_geom_1" size="0.04" type="capsule" contype="0" conaffinity="1"/>
          </body>
        </body>
      </body>
    </body>
    <light cutoff="30" diffuse="1 1 1" dir="-0 0 -1.3" directional="true" exponent="1" pos="0 0 1.3" specular=".1 .1 .1"/>
    <geom conaffinity="1" condim="3" material="MatPlane" name="worldbody_geom_1" pos="0 0 0" rgba="0.8 0.9 0.8 1" size="40 40 40" type="plane"/>
  </worldbody>
  <actuator>
    <position joint="L1_D1_joint_1" name="L1_D1_joint_1_actuator" kp="100" kv="10" ctrlrange="-2 2"/>
    <position joint="L1_D2_joint_1" name="L1_D2_joint_1_actuator" kp="100" kv="10" ctrlrange="-2 2"/>
    <position joint="L1_D3_joint_1" name="L1_D3_joint_1_actuator" kp="100" kv="10" ctrlrange="-2 2"/>
    <position joint="L2_D1_joint_1" name="L2_D1_joint_1_actuator" kp="100" kv="10" ctrlrange="-2 2"/>
    <position joint="L2_D2_joint_1" name="L2_D2_joint_1_actuator" kp="100" kv="10" ctrlrange="-2 2"/>
    <position joint="L2_D3_joint_1" name="L2_D3_joint_1_actuator" kp="100" kv="10" ctrlrange="-2 2"/>
    <position joint="L3_D1_joint_1" name="L3_D1_joint_1_actuator" kp="100" kv="10" ctrlrange="-2 2"/>
    <position joint="L3_D2_joint_1" name="L3_D2_joint_1_actuator" kp="100" kv="10" ctrlrange="-2 2"/>
    <position joint="L3_D3_joint_1" name="L3_D3_joint_1_actuator" kp="100" kv="10" ctrlrange="-2 2"/>
    <position joint="L4_D1_joint_1" name="L4_D1_joint_1_actuator" kp="100" kv="10" ctrlrange="-2 2"/>
    <position joint="L4_D2_joint_1" name="L4_D2_joint_1_actuator" kp="100" kv="10" ctrlrange="-2 2"/>
    <position joint="L4_D3_joint_1" name="L4_D3_joint_1_actuator" kp="100" kv="10" ctrlrange="-2 2"/>
  </actuator>

  <sensor>
    <gyro site="imu" name="gyro"/>
    <velocimeter site="imu" name="local_linvel"/>
    <accelerometer site="imu" name="accelerometer"/>
    <framepos objtype="site" objname="imu" name="position"/>
    <framezaxis objtype="site" objname="imu" name="upvector"/>
    <framexaxis objtype="site" objname="imu" name="forwardvector"/>
    <framelinvel objtype="site" objname="imu" name="global_linvel"/>
    <frameangvel objtype="site" objname="imu" name="global_angvel"/>
    <framequat objtype="site" objname="imu" name="orientation"/>
  </sensor>
</mujoco>
